Traceback (most recent call last):
  File "/Users/victormorales/opt/anaconda3/lib/python3.9/site-packages/jupyter_cache/executors/utils.py", line 58, in single_nb_execution
    executenb(
  File "/Users/victormorales/opt/anaconda3/lib/python3.9/site-packages/nbclient/client.py", line 1204, in execute
    return NotebookClient(nb=nb, resources=resources, km=km, **kwargs).execute()
  File "/Users/victormorales/opt/anaconda3/lib/python3.9/site-packages/nbclient/util.py", line 84, in wrapped
    return just_run(coro(*args, **kwargs))
  File "/Users/victormorales/opt/anaconda3/lib/python3.9/site-packages/nbclient/util.py", line 62, in just_run
    return loop.run_until_complete(coro)
  File "/Users/victormorales/opt/anaconda3/lib/python3.9/asyncio/base_events.py", line 647, in run_until_complete
    return future.result()
  File "/Users/victormorales/opt/anaconda3/lib/python3.9/site-packages/nbclient/client.py", line 663, in async_execute
    await self.async_execute_cell(
  File "/Users/victormorales/opt/anaconda3/lib/python3.9/site-packages/nbclient/client.py", line 965, in async_execute_cell
    await self._check_raise_for_error(cell, cell_index, exec_reply)
  File "/Users/victormorales/opt/anaconda3/lib/python3.9/site-packages/nbclient/client.py", line 862, in _check_raise_for_error
    raise CellExecutionError.from_cell_and_msg(cell, exec_reply_content)
nbclient.exceptions.CellExecutionError: An error occurred while executing the following cell:
------------------
from shared_utilities import plot_fruit_knn

plot_fruit_knn(X_train, y_train, 5, 'uniform')   # elegimos 5 vecinos mas cercanos
------------------

[0;31m---------------------------------------------------------------------------[0m
[0;31mModuleNotFoundError[0m                       Traceback (most recent call last)
Input [0;32mIn [11][0m, in [0;36m<cell line: 1>[0;34m()[0m
[0;32m----> 1[0m [38;5;28;01mfrom[39;00m [38;5;21;01mshared_utilities[39;00m [38;5;28;01mimport[39;00m plot_fruit_knn
[1;32m      3[0m plot_fruit_knn(X_train, y_train, [38;5;241m5[39m, [38;5;124m'[39m[38;5;124muniform[39m[38;5;124m'[39m)

File [0;32m~/Documents/Consultorias&Cursos/CURSOS/Cooking/MLPython/pyML/shared_utilities.py:11[0m, in [0;36m<module>[0;34m[0m
[1;32m      9[0m [38;5;28;01mfrom[39;00m [38;5;21;01msklearn[39;00m [38;5;28;01mimport[39;00m neighbors
[1;32m     10[0m [38;5;28;01mimport[39;00m [38;5;21;01mmatplotlib[39;00m[38;5;21;01m.[39;00m[38;5;21;01mpatches[39;00m [38;5;28;01mas[39;00m [38;5;21;01mmpatches[39;00m
[0;32m---> 11[0m [38;5;28;01mimport[39;00m [38;5;21;01mgraphviz[39;00m
[1;32m     12[0m [38;5;28;01mfrom[39;00m [38;5;21;01msklearn[39;00m[38;5;21;01m.[39;00m[38;5;21;01mtree[39;00m [38;5;28;01mimport[39;00m export_graphviz
[1;32m     13[0m [38;5;28;01mimport[39;00m [38;5;21;01mmatplotlib[39;00m[38;5;21;01m.[39;00m[38;5;21;01mpatches[39;00m [38;5;28;01mas[39;00m [38;5;21;01mmpatches[39;00m

[0;31mModuleNotFoundError[0m: No module named 'graphviz'
ModuleNotFoundError: No module named 'graphviz'

