Traceback (most recent call last):
  File "/Users/victormorales/opt/anaconda3/lib/python3.9/site-packages/jupyter_cache/executors/utils.py", line 58, in single_nb_execution
    executenb(
  File "/Users/victormorales/opt/anaconda3/lib/python3.9/site-packages/nbclient/client.py", line 1305, in execute
    return NotebookClient(nb=nb, resources=resources, km=km, **kwargs).execute()
  File "/Users/victormorales/opt/anaconda3/lib/python3.9/site-packages/jupyter_core/utils/__init__.py", line 173, in wrapped
    return loop.run_until_complete(inner)
  File "/Users/victormorales/opt/anaconda3/lib/python3.9/asyncio/base_events.py", line 647, in run_until_complete
    return future.result()
  File "/Users/victormorales/opt/anaconda3/lib/python3.9/site-packages/nbclient/client.py", line 705, in async_execute
    await self.async_execute_cell(
  File "/Users/victormorales/opt/anaconda3/lib/python3.9/site-packages/nbclient/client.py", line 1058, in async_execute_cell
    await self._check_raise_for_error(cell, cell_index, exec_reply)
  File "/Users/victormorales/opt/anaconda3/lib/python3.9/site-packages/nbclient/client.py", line 914, in _check_raise_for_error
    raise CellExecutionError.from_cell_and_msg(cell, exec_reply_content)
nbclient.exceptions.CellExecutionError: An error occurred while executing the following cell:
------------------
# Obtener los valores de ccp_alpha para la poda
path = credit_model.cost_complexity_pruning_path(X_train_encoded, y_train)
ccp_alphas, impurities = path.ccp_alphas, path.impurities

------------------


[0;31m---------------------------------------------------------------------------[0m
[0;31mNameError[0m                                 Traceback (most recent call last)
Cell [0;32mIn[23], line 2[0m
[1;32m      1[0m [38;5;66;03m# Obtener los valores de ccp_alpha para la poda[39;00m
[0;32m----> 2[0m path [38;5;241m=[39m [43mcredit_model[49m[38;5;241m.[39mcost_complexity_pruning_path(X_train_encoded, y_train)
[1;32m      3[0m ccp_alphas, impurities [38;5;241m=[39m path[38;5;241m.[39mccp_alphas, path[38;5;241m.[39mimpurities

[0;31mNameError[0m: name 'credit_model' is not defined

