Traceback (most recent call last):
  File "/Users/victormorales/opt/anaconda3/lib/python3.9/site-packages/jupyter_cache/executors/utils.py", line 58, in single_nb_execution
    executenb(
  File "/Users/victormorales/opt/anaconda3/lib/python3.9/site-packages/nbclient/client.py", line 1204, in execute
    return NotebookClient(nb=nb, resources=resources, km=km, **kwargs).execute()
  File "/Users/victormorales/opt/anaconda3/lib/python3.9/site-packages/nbclient/util.py", line 84, in wrapped
    return just_run(coro(*args, **kwargs))
  File "/Users/victormorales/opt/anaconda3/lib/python3.9/site-packages/nbclient/util.py", line 62, in just_run
    return loop.run_until_complete(coro)
  File "/Users/victormorales/opt/anaconda3/lib/python3.9/asyncio/base_events.py", line 647, in run_until_complete
    return future.result()
  File "/Users/victormorales/opt/anaconda3/lib/python3.9/site-packages/nbclient/client.py", line 663, in async_execute
    await self.async_execute_cell(
  File "/Users/victormorales/opt/anaconda3/lib/python3.9/site-packages/nbclient/client.py", line 965, in async_execute_cell
    await self._check_raise_for_error(cell, cell_index, exec_reply)
  File "/Users/victormorales/opt/anaconda3/lib/python3.9/site-packages/nbclient/client.py", line 862, in _check_raise_for_error
    raise CellExecutionError.from_cell_and_msg(cell, exec_reply_content)
nbclient.exceptions.CellExecutionError: An error occurred while executing the following cell:
------------------
$$D_{i} = \beta_{0}+\beta_{1}X_{1i}+u_{i}$$


Veamos un ejemplo: Abrir la base `MROZ` de Wooldridge y ajuste el modelo:

$$inlf=\beta_0nwifeinc+\beta_1educ + \beta_2exper +\beta_3expersq + \beta_4age + \beta_5kidslt6 + \beta_6kidsge6$$
------------------

[0;36m  Input [0;32mIn [1][0;36m[0m
[0;31m    $$D_{i} = \beta_{0}+\beta_{1}X_{1i}+u_{i}$$[0m
[0m    ^[0m
[0;31mSyntaxError[0m[0;31m:[0m invalid syntax

SyntaxError: invalid syntax (1839493294.py, line 1)

