Traceback (most recent call last):
  File "/Users/victormorales/opt/anaconda3/lib/python3.9/site-packages/jupyter_cache/executors/utils.py", line 58, in single_nb_execution
    executenb(
  File "/Users/victormorales/opt/anaconda3/lib/python3.9/site-packages/nbclient/client.py", line 1204, in execute
    return NotebookClient(nb=nb, resources=resources, km=km, **kwargs).execute()
  File "/Users/victormorales/opt/anaconda3/lib/python3.9/site-packages/nbclient/util.py", line 84, in wrapped
    return just_run(coro(*args, **kwargs))
  File "/Users/victormorales/opt/anaconda3/lib/python3.9/site-packages/nbclient/util.py", line 62, in just_run
    return loop.run_until_complete(coro)
  File "/Users/victormorales/opt/anaconda3/lib/python3.9/asyncio/base_events.py", line 647, in run_until_complete
    return future.result()
  File "/Users/victormorales/opt/anaconda3/lib/python3.9/site-packages/nbclient/client.py", line 663, in async_execute
    await self.async_execute_cell(
  File "/Users/victormorales/opt/anaconda3/lib/python3.9/site-packages/nbclient/client.py", line 965, in async_execute_cell
    await self._check_raise_for_error(cell, cell_index, exec_reply)
  File "/Users/victormorales/opt/anaconda3/lib/python3.9/site-packages/nbclient/client.py", line 862, in _check_raise_for_error
    raise CellExecutionError.from_cell_and_msg(cell, exec_reply_content)
nbclient.exceptions.CellExecutionError: An error occurred while executing the following cell:
------------------
import numpy as np
xrange = np.linspace(-2, 2, 200)

plt.figure(figsize=(7,6))

plt.plot(xrange, np.maximum(xrange, 0), label = 'relu')
plt.plot(xrange, np.tanh(xrange), label = 'tanh')
plt.plot(xrange, 1 / (1 + np.exp(-xrange)), label = 'logistic')
plt.legend()
plt.title('Funciones de activaci√≥n para redes neuronales')
plt.xlabel('Input(x)')
plt.ylabel('Output: funci√≥n de activaci√≥n')

plt.show()
------------------

[0;31m---------------------------------------------------------------------------[0m
[0;31mNameError[0m                                 Traceback (most recent call last)
Input [0;32mIn [2][0m, in [0;36m<cell line: 4>[0;34m()[0m
[1;32m      1[0m [38;5;28;01mimport[39;00m [38;5;21;01mnumpy[39;00m [38;5;28;01mas[39;00m [38;5;21;01mnp[39;00m
[1;32m      2[0m xrange [38;5;241m=[39m np[38;5;241m.[39mlinspace([38;5;241m-[39m[38;5;241m2[39m, [38;5;241m2[39m, [38;5;241m200[39m)
[0;32m----> 4[0m [43mplt[49m[38;5;241m.[39mfigure(figsize[38;5;241m=[39m([38;5;241m7[39m,[38;5;241m6[39m))
[1;32m      6[0m plt[38;5;241m.[39mplot(xrange, np[38;5;241m.[39mmaximum(xrange, [38;5;241m0[39m), label [38;5;241m=[39m [38;5;124m'[39m[38;5;124mrelu[39m[38;5;124m'[39m)
[1;32m      7[0m plt[38;5;241m.[39mplot(xrange, np[38;5;241m.[39mtanh(xrange), label [38;5;241m=[39m [38;5;124m'[39m[38;5;124mtanh[39m[38;5;124m'[39m)

[0;31mNameError[0m: name 'plt' is not defined
NameError: name 'plt' is not defined

