Traceback (most recent call last):
  File "/opt/anaconda3/lib/python3.12/site-packages/jupyter_cache/executors/utils.py", line 58, in single_nb_execution
    executenb(
  File "/opt/anaconda3/lib/python3.12/site-packages/nbclient/client.py", line 1305, in execute
    return NotebookClient(nb=nb, resources=resources, km=km, **kwargs).execute()
           ^^^^^^^^^^^^^^^^^^^^^^^^^^^^^^^^^^^^^^^^^^^^^^^^^^^^^^^^^^^^^^^^^^^^^
  File "/opt/anaconda3/lib/python3.12/site-packages/jupyter_core/utils/__init__.py", line 165, in wrapped
    return loop.run_until_complete(inner)
           ^^^^^^^^^^^^^^^^^^^^^^^^^^^^^^
  File "/opt/anaconda3/lib/python3.12/asyncio/base_events.py", line 687, in run_until_complete
    return future.result()
           ^^^^^^^^^^^^^^^
  File "/opt/anaconda3/lib/python3.12/site-packages/nbclient/client.py", line 705, in async_execute
    await self.async_execute_cell(
  File "/opt/anaconda3/lib/python3.12/site-packages/nbclient/client.py", line 1058, in async_execute_cell
    await self._check_raise_for_error(cell, cell_index, exec_reply)
  File "/opt/anaconda3/lib/python3.12/site-packages/nbclient/client.py", line 914, in _check_raise_for_error
    raise CellExecutionError.from_cell_and_msg(cell, exec_reply_content)
nbclient.exceptions.CellExecutionError: An error occurred while executing the following cell:
------------------
# Mostrar coeficientes con nombres
ridge_coefficients = pd.DataFrame(ridge.coef_, index=X.columns, columns=['Ridge Coefficients'])
lasso_coefficients = pd.DataFrame(lasso.coef_, index=X.columns, columns=['Lasso Coefficients'])
ols_coefficients = pd.DataFrame(regOLS.coef_, index=X.columns, columns=['OLS Coefficients'])

# Combinar coeficientes en un solo DataFrame
coefficients = pd.concat([ridge_coefficients, lasso_coefficients,ols_coefficients], axis=1)
print("\nCoeficientes:")
print(coefficients)
------------------


[0;31m---------------------------------------------------------------------------[0m
[0;31mAttributeError[0m                            Traceback (most recent call last)
Cell [0;32mIn[13], line 2[0m
[1;32m      1[0m [38;5;66;03m# Mostrar coeficientes con nombres[39;00m
[0;32m----> 2[0m ridge_coefficients [38;5;241m=[39m pd[38;5;241m.[39mDataFrame(ridge[38;5;241m.[39mcoef_, index[38;5;241m=[39mX[38;5;241m.[39mcolumns, columns[38;5;241m=[39m[[38;5;124m'[39m[38;5;124mRidge Coefficients[39m[38;5;124m'[39m])
[1;32m      3[0m lasso_coefficients [38;5;241m=[39m pd[38;5;241m.[39mDataFrame(lasso[38;5;241m.[39mcoef_, index[38;5;241m=[39mX[38;5;241m.[39mcolumns, columns[38;5;241m=[39m[[38;5;124m'[39m[38;5;124mLasso Coefficients[39m[38;5;124m'[39m])
[1;32m      4[0m ols_coefficients [38;5;241m=[39m pd[38;5;241m.[39mDataFrame(regOLS[38;5;241m.[39mcoef_, index[38;5;241m=[39mX[38;5;241m.[39mcolumns, columns[38;5;241m=[39m[[38;5;124m'[39m[38;5;124mOLS Coefficients[39m[38;5;124m'[39m])

[0;31mAttributeError[0m: 'numpy.ndarray' object has no attribute 'columns'

